Traceback (most recent call last):
  File "/Users/hildeweerts/opt/anaconda3/envs/book/lib/python3.9/site-packages/jupyter_cache/executors/utils.py", line 51, in single_nb_execution
    executenb(
  File "/Users/hildeweerts/opt/anaconda3/envs/book/lib/python3.9/site-packages/nbclient/client.py", line 1112, in execute
    return NotebookClient(nb=nb, resources=resources, km=km, **kwargs).execute()
  File "/Users/hildeweerts/opt/anaconda3/envs/book/lib/python3.9/site-packages/nbclient/util.py", line 74, in wrapped
    return just_run(coro(*args, **kwargs))
  File "/Users/hildeweerts/opt/anaconda3/envs/book/lib/python3.9/site-packages/nbclient/util.py", line 53, in just_run
    return loop.run_until_complete(coro)
  File "/Users/hildeweerts/opt/anaconda3/envs/book/lib/python3.9/asyncio/base_events.py", line 642, in run_until_complete
    return future.result()
  File "/Users/hildeweerts/opt/anaconda3/envs/book/lib/python3.9/site-packages/nbclient/client.py", line 553, in async_execute
    await self.async_execute_cell(
  File "/Users/hildeweerts/opt/anaconda3/envs/book/lib/python3.9/site-packages/nbclient/client.py", line 857, in async_execute_cell
    self._check_raise_for_error(cell, exec_reply)
  File "/Users/hildeweerts/opt/anaconda3/envs/book/lib/python3.9/site-packages/nbclient/client.py", line 760, in _check_raise_for_error
    raise CellExecutionError.from_cell_and_msg(cell, exec_reply_content)
nbclient.exceptions.CellExecutionError: An error occurred while executing the following cell:
------------------
# data wrangling
import pandas as pd
import numpy as np

# visualization
import matplotlib.pyplot as plt

# measuring fairness
from fairlearn.metrics import (
    MetricFrame,
    make_derived_metric,
    selection_rate,
    false_positive_rate,
    false_negative_rate,
    demographic_parity_difference,
    equalized_odds_difference,
)
from sklearn.metrics import precision_score
from sklearn.calibration import calibration_curve
------------------

[0;31m---------------------------------------------------------------------------[0m
[0;31mModuleNotFoundError[0m                       Traceback (most recent call last)
[0;32m/var/folders/gm/3mj2p8yj7r3_gvrx0j6yz0tm0000gn/T/ipykernel_55768/2327387754.py[0m in [0;36m<module>[0;34m[0m
[1;32m      1[0m [0;31m# data wrangling[0m[0;34m[0m[0;34m[0m[0;34m[0m[0m
[0;32m----> 2[0;31m [0;32mimport[0m [0mpandas[0m [0;32mas[0m [0mpd[0m[0;34m[0m[0;34m[0m[0m
[0m[1;32m      3[0m [0;32mimport[0m [0mnumpy[0m [0;32mas[0m [0mnp[0m[0;34m[0m[0;34m[0m[0m
[1;32m      4[0m [0;34m[0m[0m
[1;32m      5[0m [0;31m# visualization[0m[0;34m[0m[0;34m[0m[0;34m[0m[0m

[0;31mModuleNotFoundError[0m: No module named 'pandas'
ModuleNotFoundError: No module named 'pandas'

